<?xml version="1.0"?>
<robot name="robo" xmlns:xacro="http://www.ros.org/wiki/xacro">
<xacro:include filename="$(find robo_description)/urdf/materials.xacro"/>
<xacro:include filename="$(find robo_description)/urdf/robo.gazebo"/> 
<!-- base and base link -->
<link name="base_footprint">
    
</link>
<joint name="chaseToBaseFootPrint" type="fixed">
    <origin xyz="0.0 0.0 0.11" rpy="0.0 0.0 0.0"/>
    <parent link="base_footprint"/>
    <child link="chase"/>
    <axis xyz="0.0 0.0 0.0"/>
    <limit lower="0.0" upper="0.0" effort="0.0" velocity="0.0"/>
</joint>
<link name="chase">
    <inertial>
        <origin xyz="0.0 0.0 0.0" rpy="0.0 0.0 0.0"/>
        <mass value="1.0"/>
        <inertia ixx="0.0" ixy="0.0" ixz="0.0" iyy="0.0" iyz="0.0" izz="0.0"/>
    </inertial>
    <visual >
        <origin xyz="0.0 0.0 0.0" rpy="0.0 0.0 0.0"/>
        <geometry>
            <box size="0.6 0.4 0.15"/>
        </geometry>
        <material name="black">
        <!--<color rgba="0.0 0.0 1.0 0.0"/>-->
        </material>
    </visual>
    <collision>
        <origin xyz="0.0 0.0 0.0" rpy="0.0 0.0 0.0"/>
        <geometry>
            <box size="0.6 0.4 0.2"/>
        </geometry>
    </collision>
</link>
<!--  forward left -->
<link name="f_l_wheel">
    <inertial>
        <origin xyz="0.0 0.0 0.0" rpy="0.0 0.0 0.0"/>
        <mass value="1.0"/>
        <inertia ixx="0.0" ixy="0.0" ixz="0.0" iyy="0.0" iyz="0.0" izz="0.0"/>
    </inertial>
    <visual name="">
        <origin xyz="0.0 0.0 0.0" rpy="0.0 0.0 0.0"/>
        <geometry>
            <cylinder radius="0.07" length="0.05"/>
        </geometry>
        <material name="white">
        <!--<color rgba="0.0 0.0 1.0 0.0"/>-->
        </material>
    </visual>
    <collision>
        <origin xyz="0.0 0.0 0.0" rpy="0.0 0.0 0.0"/>
        <geometry>
            <cylinder radius="0.07" length="0.05"/>
        </geometry>
    </collision>
</link>
<joint name="f_l_wheelToBase" type="continuous">

    <origin xyz="0.20 0.225 -0.075" rpy="0.0 1.57 1.57"/>
    <parent link="chase"/>
    <child link="f_l_wheel"/>
    <axis xyz="0.0 0.0 1.0"/>
    <limit lower="0.0" upper="0.0" effort="0.0" velocity="0.0"/>
</joint>
<!--  rear left -->
<link name="r_l_wheel">
    <inertial>
        <origin xyz="0.0 0.0 0.0" rpy="0.0 0.0 0.0"/>
        <mass value="1.0"/>
        <inertia ixx="0.0" ixy="0.0" ixz="0.0" iyy="0.0" iyz="0.0" izz="0.0"/>
    </inertial>
    <visual name="">
        <origin xyz="0.0 0.0 0.0" rpy="0.0 0.0 0.0"/>
        <geometry>
            <cylinder radius="0.07" length="0.05"/>
        </geometry>
         <material name="white">
         <!--<color rgba="0.0 0.0 1.0 0.0"/>-->
        </material>
    </visual>
    <collision>
        <origin xyz="0.0 0.0 0.0" rpy="0.0 0.0 0.0"/>
        <geometry>
            <cylinder radius="0.07" length="0.05"/>
        </geometry>
    </collision>
</link>
<joint name="r_l_wheelToBase" type="continuous">
    <origin xyz="-0.20 0.225 -0.075" rpy="0.0 1.57 1.57"/>
    <parent link="chase"/>
    <child link="r_l_wheel"/>
    <axis xyz="0.0 0.0 1.0"/>
</joint>
<!--  rear right -->
<link name="r_r_wheel">
    <inertial>
        <origin xyz="0.0 0.0 0.0" rpy="0.0 0.0 0.0"/>
        <mass value="1.0"/>
        <inertia ixx="0.0" ixy="0.0" ixz="0.0" iyy="0.0" iyz="0.0" izz="0.0"/>
    </inertial>
    <visual name="">
        <origin xyz="0.0 0.0 0.0" rpy="0.0 0.0 0.0"/>
        <geometry>
            <cylinder radius="0.07" length="0.05"/>
        </geometry>
         <material name="white">
         <!--<color rgba="0.0 0.0 1.0 0.0"/>-->
        </material>
    </visual>
    <collision>
        <origin xyz="0.0 0.0 0.0" rpy="0.0 0.0 0.0"/>
        <geometry>
            <cylinder radius="0.07" length="0.05"/>
        </geometry>
    </collision>
</link>
<joint name="r_r_wheelToBase" type="continuous">
    <origin xyz="-0.20 -0.225 -0.075" rpy="0.0 1.57 1.57"/>
    <parent link="chase"/>
    <child link="r_r_wheel"/>
    <axis xyz="0.0 0.0 1.0"/>
</joint>
<!--  front right -->
<link name="f_r_wheel">
    <inertial>
        <origin xyz="0.0 0.0 0.0" rpy="0.0 0.0 0.0"/>
        <mass value="1.0"/>
        <inertia ixx="0.0" ixy="0.0" ixz="0.0" iyy="0.0" iyz="0.0" izz="0.0"/>
    </inertial>
    <visual name="">
        <origin xyz="0.0 0.0 0.0" rpy="0.0 0.0 0.0"/>
        <geometry>
            <cylinder radius="0.07" length="0.05"/>
        </geometry>
         <material name="white">
         <!--<color rgba="0.0 0.0 1.0 0.0"/>-->
        </material>
    </visual>
    <collision>
        <origin xyz="0.0 0.0 0.0" rpy="0.0 0.0 0.0"/>
        <geometry>
            <cylinder radius=".07" length="0.05"/>
        </geometry>
    </collision>
</link>
<joint name="f_r_wheelToBase" type="continuous">
    <origin xyz="0.20 -0.225 -0.075" rpy="0.0 1.57 1.57"/>
    <parent link="chase"/>
    <child link="f_r_wheel"/>
    <axis xyz="0.0 0.0 1.0"/>
</joint>
    <!--  camera link -->
    <link name="camera">
        <inertial>
            <origin xyz="0.0 0.0 0.0" rpy="0.0 0.0 0.0"/>
            <mass value="1.0"/>
            <inertia ixx="0.0" ixy="0.0" ixz="0.0" iyy="0.0" iyz="0.0" izz="0.0"/>
        </inertial>
        <visual name="">
            <origin xyz="0.0 0.0 0.0" rpy="0.0 0.0 0.0"/>
            <geometry>
                <box size="0.005 0.2 0.05"/>
            </geometry>
            <material name="">
                <color rgba="1.0 1.0 1.0 1.0"/>
                <texture filename=""/>
            </material>
        </visual>
        <collision>
            <origin xyz="0.0 0.0 0.0" rpy="0.0 0.0 0.0"/>
            <geometry>
               <box size="0.005 0.2 0.075"/>
            </geometry>
        </collision>
    </link>


    <joint name="cameraTObase" type="fixed">
        <origin xyz="0.3 0.0 0.0" rpy="0.0 0.0 0.0"/>
        <parent link="chase"/>
        <child link="camera"/>
        <axis xyz="0.0 0.0 0.0"/>
        <limit lower="0.0" upper="0.0" effort="0.0" velocity="0.0"/>
    </joint>
    <!-- lidar link -->
    <joint name="laser_joint" type="fixed">
        <parent link="chase"/>
        <child link="laser_frame"/>
        <origin xyz="0.1 0 .1" rpy="0 0 0"/>
    </joint>
 
    <link name="laser_frame">
        <visual>
            <geometry>
                <cylinder radius="0.05" length="0.04"/>
            </geometry>
            <material name="red"/>
        </visual>
        <collision>
            <geometry>
                <cylinder radius="0.05" length="0.04"/>
            </geometry>
         </collision>
         <inertial>
            <origin xyz="0.0 0.0 0.0" rpy="0.0 0.0 0.0"/>
            <mass value="1.0"/>
            <inertia ixx="0.0" ixy="0.0" ixz="0.0" iyy="0.0" iyz="0.0" izz="0.0"/>
         </inertial>
    </link>
</robot>
